<?xml version="1.0"?>

<robot xmlns="http://drake.mit.edu"
 xmlns:xsi="http://www.w3.org/2001/XMLSchema-instance"
 name="sqwip">

  <link name="base">
    <inertial>
      <origin xyz="0 0 0" rpy="0 0 0" />
      <mass value="2" />
      <inertia ixx="0.013" ixy="0" ixz="0" iyy="0.1133" iyz="0" izz="0.1133" />
    </inertial>
    <visual>
      <origin xyz="0 0 0" rpy="0 0 0" />
      <geometry>
        <box size="0.8 0.2  0.2" />
      </geometry>
      <material>
        <color rgba="0 1 0 1" />
      </material>
    </visual>
  </link>

  <joint name="base_world_joint" type="planar">
    <parent link="world" />
    <child link="base" />
    <origin xyz="0 0 0" />
    <axis xyz="0 1 0" />
  </joint>

   <link name="hind_hip_link">
    <inertial>
      <origin xyz="0 0 0" rpy="0 0 0" />
      <mass value="0.03" />
      <inertia ixx="0" ixy="0" ixz="0" iyy="0" iyz="0" izz="0" />
    </inertial>
    <visual>
      <origin xyz="0 0 -0.075" rpy="0 0 0" />
      <geometry>
         <cylinder length="0.15" radius=".01" />
      </geometry>
      <material>
        <color rgba="1 0 0 1" />
      </material>
    </visual>
  </link>

  <joint name="hind_hip_joint" type="revolute">
    <origin xyz="-0.30 0 -0.1" rpy="0 0 0" />
    <parent link="base" />
    <child link="hind_hip_link" />
    <axis xyz="0 1 0" />
  </joint>

  <link name="hind_knee_link">
    <inertial>
      <origin xyz="0 0 0" rpy="0 0 0" />
      <mass value="0.03" />
      <inertia ixx="0" ixy="0" ixz="0" iyy="0" iyz="0" izz="0" />
    </inertial>
    <visual>
      <origin xyz="0 0 -0.075" rpy="0 0 0" />
      <geometry>
         <cylinder length="0.15" radius=".01" />
      </geometry>
      <material>
        <color rgba="1 0 0 1" />
      </material>
    </visual>
  </link>

  <joint name="hind_knee_joint" type="revolute">
    <origin xyz="0 0 -0.15" rpy="0 0 0" />
    <parent link="hind_hip_link" />
    <child link="hind_knee_link" />
    <axis xyz="0 1 0" />
  </joint>

  <link name="hind_feet_link">
  <visual>
      <origin xyz="0 0 0" rpy="0 0 0" />
      <geometry>
        <sphere radius=".01" />
      </geometry>
      <material>
        <color rgba="0 0 1 1" />
      </material>
    </visual>
  </link>
  <joint name="hind_feet_joint" type="fixed">
    <origin xyz="0 0 -0.15" rpy="0 0 0" />
    <parent link="hind_knee_link" />
    <child link="hind_feet_link" />
  </joint>


  <link name="front_hip_link">
    <inertial>
      <origin xyz="0 0 0" rpy="0 0 0" />
      <mass value="0.03" />
      <inertia ixx="0" ixy="0" ixz="0" iyy="0" iyz="0" izz="0" />
    </inertial>
    <visual>
      <origin xyz="0 0 -0.075" rpy="0 0 0" />
      <geometry>
         <cylinder length="0.15" radius=".01" />
      </geometry>
      <material>
        <color rgba="1 0 0 1" />
      </material>
    </visual>
  </link>

  <joint name="front_hip_joint" type="revolute">
    <origin xyz="0.30 0 -0.1" rpy="0 0 0" />
    <parent link="base" />
    <child link="front_hip_link" />
    <axis xyz="0 1 0" />
  </joint>

  <link name="front_knee_link">
    <inertial>
      <origin xyz="0 0 0" rpy="0 0 0" />
      <mass value="0.03" />
      <inertia ixx="0" ixy="0" ixz="0" iyy="0" iyz="0" izz="0" />
    </inertial>
    <visual>
      <origin xyz="0 0 -0.075" rpy="0 0 0" />
      <geometry>
         <cylinder length="0.15" radius=".01" />
      </geometry>
      <material>
        <color rgba="1 0 0 1" />
      </material>
    </visual>
  </link>

  <joint name="front_knee_joint" type="revolute">
    <origin xyz="0 0 -0.15" rpy="0 0 0" />
    <parent link="front_hip_link" />
    <child link="front_knee_link" />
    <axis xyz="0 1 0" />
  </joint>

  <link name="front_feet_link">
  <visual>
      <origin xyz="0 0 0" rpy="0 0 0" />
      <geometry>
        <sphere radius=".01" />
      </geometry>
      <material>
        <color rgba="0 0 1 1" />
      </material>
    </visual>
  </link>
  <joint name="front_feet_joint" type="fixed">
    <origin xyz="0 0 -0.15" rpy="0 0 0" />
    <parent link="front_knee_link" />
    <child link="front_feet_link" />
  </joint>

  <transmission type="SimpleTransmission" name="hind_hip_trans">
    <actuator name="hind_hip_joint" />
    <joint name="hind_hip_joint" />
    <mechanicalReduction>1</mechanicalReduction>
  </transmission>

  <transmission type="SimpleTransmission" name="hind_knee_trans">
    <actuator name="hind_knee_joint" />
    <joint name="hind_knee_joint" />
    <mechanicalReduction>1</mechanicalReduction>
  </transmission>

  <transmission type="SimpleTransmission" name="front_hip_trans">
    <actuator name="front_hip_joint" />
    <joint name="front_hip_joint" />
    <mechanicalReduction>1</mechanicalReduction>
  </transmission>

  <transmission type="SimpleTransmission" name="front_knee_trans">
    <actuator name="front_knee_joint" />
    <joint name="front_knee_joint" />
    <mechanicalReduction>1</mechanicalReduction>
  </transmission>


  



  <link name="pole">
    <inertial>
      <origin xyz="0 0 -.5" rpy="0 0 0" />
      <mass value="1" />
      <inertia ixx="0" ixy="0" ixz="0" iyy="0" iyz="0" izz="0" />
    </inertial>
    <visual>
      <origin xyz="0 0 -.15" rpy="0 0 0" />
      <geometry>
         <cylinder length=".3" radius=".01" />
      </geometry>
      <material>
        <color rgba="1 0 0 1" />
      </material>
    </visual>
    <visual>
      <origin xyz="0 0 -.3" rpy="0 0 0" />
      <geometry>
         <sphere radius=".05" />
      </geometry>
      <material>
        <color rgba="0 0 1 1" />
      </material>
    </visual>
  </link>
  

  <joint name="pole_joint" type="continuous">
    <parent link="base" />
    <child link="pole" />
    <origin xyz="0 0 0.1" />
    <axis xyz="0 1 0" />
  </joint>

</robot>